Workbook

Sheet Summary
B2: Duble//Slash · Financial Model
B3: Seed Round · May 2026 — Projections through Dec 2027
B5: WHAT'S IN THIS WORKBOOK
B6: Inputs | C6: All editable assumptions (yellow cells). Change a number here → everything updates.
B7: Unit Economics | C7: LTV, CAC, gross margin, break-even — derived from Inputs.
B8: Projections | C8: 3 scenarios (Conservative / Base / Optimistic) month by month, Oct 2026–Dec 2027.
B9: Burn & Cash | C9: Monthly P&L and cash runway from the $1.5M seed, based on Base scenario.
B11: KEY METRICS · June 2027 (Series A trigger)
B12: Metric | C12: Conservative | D12: Base | E12: Optimistic
B13: Paying teams · Jun 2027 | C13: ~220 | D13: ~367 | E13: ~589
B14: MRR · Jun 2027 | C14: $10,800 | D14: $18,000 | E14: $28,900
B15: ARR · Jun 2027 | C15: $129k | D15: $216k | E15: $347k
B17: Price / seat / month | C17: $14 | D17: $14 | E17: $14
B18: Avg team size | C18: 3.5 seats | D18: 3.5 seats | E18: 3.5 seats
B19: Gross margin (infra) | C19: ~99% | D19: ~99% | E19: ~99%
B20: Monthly team churn | C20: 3% | D20: 3% | E20: 3%
B22: Realistic Series A ARR | C22: ~$130k | D22: ~$216k | E22: ~$347k
B24: ROADMAP MILESTONES
B25: May 2026 | C25: OSS Launch | D25: 4 operators · npx install · macOS menu-bar · launch articles
B26: Jul 2026 | C26: V1 Free Launch | D26: Context Cloud + // injection + target: 1,000 free users
B27: Oct 2026 | C27: Paid Tier Opens | D27: Team tier $14/seat/mo · shared contexts · handoffs · analytics
B28: Jan 2027 | C28: Series A Prep | D28: Deck ready · 200–400 teams paying · ARR: $100–250k
B29: Jun 2027 | C29: Series A Trigger | D29: $130k–$347k ARR depending on scenario
B30: H2 2027 | C30: Enterprise Pilots | D30: Figma / Linear / GitHub bridges · Process telemetry · V2

Sheet Inputs
B2: Inputs & Assumptions
B3: Yellow cells = editable. All other sheets derive from column D.
B5: ← Yellow = editable input
B7: PRICING
B8: Category | C8: Parameter | D8: Value | E8: Notes / Explanation
B9: Pricing | C9: Price per seat / month | D9: 14 | E9: Team tier only — individual use is permanently free
B10: Pricing | C10: Average team size (seats) | D10: 3.5 | E10: First-wave studios are small (3–4 seats); grows over time
B11: Pricing | C11: ACV per team / month | D11: =D9*D10 | E11: Derived: seat price × avg team size
B12: Pricing | C12: ACV per team / year | D12: =D11*12 | E12: Derived: monthly × 12
B14: COST OF GOODS SOLD (infrastructure per seat)
B15: Category | C15: Parameter | D15: Value | E15: Notes / Explanation
B16: Infrastructure | C16: COGS per seat / month | D16: 0.08 | E16: Local-first (Ollama). Cloud stores backup only — S3 ~500MB/user avg.
B17: Infrastructure | C17: COGS per team / month | D17: =D16*D10 | E17: Derived: COGS/seat × avg team size
B18: Infrastructure | C18: Gross margin (infra) | D18: =(D9-D16)/D9 | E18: ~99% — the business cost is people, not infrastructure
B20: SEED FUNDING & BURN
B21: Category | C21: Parameter | D21: Value | E21: Notes / Explanation
B22: Fundraise | C22: Seed raise (total) | D22: 1500000 | E22: Pre-money negotiated; 18-month runway
B23: Fundraise | C23: Runway (months) | D23: 18 | E23: Target runway from close to Series A
B24: Burn | C24: Monthly burn rate | D24: =D22/D23 | E24: Derived: total raise ÷ runway
B25: Burn | C25: Engineering % | D25: 0.35 | E25: 2 hires: platform eng (capture/injection) + systems eng (cloud)
B26: Burn | C26: GTM % | D26: 0.55 | E26: Founder launch, content, partner programs, Config/UXLive/DevDay
B27: Burn | C27: Infrastructure % | D27: 0.1 | E27: Hosted backend, CDN, observability, security audit (pre-paid)
B28: Burn | C28: Engineering / month | D28: =D24*D25 | E28: Derived
B29: Burn | C29: GTM / month | D29: =D24*D26 | E29: Derived — this also sets CAC in Growth section
B30: Burn | C30: Infrastructure (OpEx) / mo | D30: =D24*D27 | E30: Derived
B32: GROWTH & RETENTION
B33: Category | C33: Parameter | D33: Value | E33: Notes / Explanation
B34: Retention | C34: Monthly team churn rate | D34: 0.03 | E34: 3% = moderate. Best-in-class hits 1–2%. Assumed to improve post-PMF.
B35: Retention | C35: Avg team lifespan (months) | D35: =1/D34 | E35: Derived: 1 ÷ churn rate. At 3% → 33 months.
B36: Retention | C36: LTV per team | D36: =D11*D35 | E36: Monthly ACV × avg lifespan
B37: Retention | C37: CAC (base scenario, GTM) | D37: =D29/25 | E37: GTM monthly spend ÷ 25 new teams/mo (base launch rate). Falls as organic grows
B38: Retention | C38: LTV:CAC (early stage) | D38: =D36/D37 | E38: <1× early is normal seed-stage. Target >3× at scale (see Unit Economics)
B40: GROWTH SCENARIOS — new paying teams / month
B41: Scenario | C41: Parameter | D41: Value | E41: Rationale
B42: Conservative | C42: New teams at launch (Oct 2026) | D42: 15 | E42: ~4 pilot studios + immediate network; tight but high-trust Israeli design cluster
B43: Conservative | C43: Monthly growth in new teams | D43: 3 | E43: Slow word-of-mouth. +3 new teams every month on top of previous month's rate
B45: Base | C45: New teams at launch (Oct 2026) | D45: 25 | E45: Pilot studios + network + early OSS converts. ~5% of 500 aware orgs pay immediately
B46: Base | C46: Monthly growth in new teams | D46: 5 | E46: Content + conferences (Config 2026 etc.) drive sustained organic discovery
B48: Optimistic | C48: New teams at launch (Oct 2026) | D48: 40 | E48: OSS breakout + viral conference moment. ~4% of 1,000 aware orgs convert at launch
B49: Optimistic | C49: Monthly growth in new teams | D49: 8 | E49: Anthropic partner placement + one big content hit sustains high monthly inflow

Sheet Unit Economics
B2: Unit Economics
B3: All values derive from Inputs sheet. Edit yellow cells there → this sheet updates.
B5: REVENUE METRICS
B6: Metric | C6: Value | D6: Explanation
B7: Price per seat / month | C7: =Inputs!D9 | D7: Team tier only; individuals are free forever
B8: Average team size | C8: =Inputs!D10 | D8: Seats per paying team — first wave: 3–4 seats (small studios)
B9: Monthly revenue per team | C9: =Inputs!D11 | D9: ACV/team/month
B10: Annual revenue per team | C10: =Inputs!D12 | D10: ACV/team/year — used for ARR and investor metrics
B12: COST OF GOODS SOLD
B13: Metric | C13: Value | D13: Explanation
B14: Infrastructure COGS / seat / month | C14: =Inputs!D16 | D14: Storage + sync on local-first model. Cloud = backup only.
B15: Infrastructure COGS / team / month | C15: =Inputs!D17 | D15: COGS/seat × avg team size
B16: Gross margin (infrastructure only) | C16: =Inputs!D18 | D16: ~99%. The cost structure is people, not infrastructure.
B18: CUSTOMER ACQUISITION & LIFETIME VALUE
B19: Metric | C19: Value | D19: Explanation
B20: Monthly team churn rate | C20: =Inputs!D34 | D20: 3% monthly. Best-in-class team tools: 1–2%.
B21: Average team lifespan | C21: =Inputs!D35 | D21: 1 ÷ churn rate. At 3%: ~33 months.
B22: LTV per team | C22: =Inputs!D36 | D22: Monthly ACV × avg lifespan = total revenue per team
B23: CAC — base scenario (GTM-funded) | C23: =Inputs!D37 | D23: GTM monthly spend ÷ 25 new teams/mo at base launch
B24: LTV:CAC — early stage | C24: =Inputs!D38 | D24: <1× early is expected. Path to >3× at scale (see notes)
B26: WHY LTV:CAC < 1× IS OK AT SEED STAGE: • GTM spend of $46k/mo is high relative to early $49/mo ARPU per team. • As teams/month scale from 25 → 100+, the same GTM budget makes CAC drop from ~$1,840 → ~$460. • At $460 CAC: LTV:CAC = $1,617 / $460 = 3.5× — well above the '>3× healthy' benchmark. • Additionally, organic channels (OSS community, content, methodology-as-distribution) are not in the CAC calc. When 50%+ of acquisition is organic, effective CAC halves → LTV:CAC doubles. Investors in seed-stage SaaS accept <1× LTV:CAC when: (a) 70%+ gross margin, (b) clear path to >3× at scale. DS has both: 99% gross margin and a demonstrable scale curve on CAC.
B28: BREAK-EVEN
B29: Metric | C29: Value | D29: Explanation
B30: Monthly burn rate | C30: =Inputs!D24 | D30: Total seed ÷ runway months
B31: MRR to break even | C31: =Inputs!D24 | D31: ≈ burn (gross margin ~99%)
B32: Paid seats to break even | C32: =Inputs!D24/Inputs!D9 | D32: MRR target ÷ price/seat
B33: Paying teams to break even | C33: =Inputs!D24/Inputs!D11 | D33: MRR target ÷ ACV/team
B34: Break-even (~1,700 teams) is a Series B target. The seed funds growth to Series A (150–400 teams).

Sheet Projections
B2: Revenue Projections · Oct 2026 – Dec 2027
B3: Three scenarios. Assumptions in Inputs sheet. Highlighted rows = June 2027 (Series A trigger).
B5: CONSERVATIVE · 15 teams at launch / +3 teams / month
B6: Month | C6: New teams | D6: Churned | E6: Cumulative teams | F6: MRR | G6: ARR (run-rate)
B7: Oct 2026 | C7: 15 | D7: 0 | E7: 15 | F7: 735 | G7: 8820
B8: Nov 2026 | C8: 18 | D8: 0 | E8: 33 | F8: 1617 | G8: 19404
B9: Dec 2026 | C9: 21 | D9: 1 | E9: 53 | F9: 2597 | G9: 31164
B10: Jan 2027 | C10: 24 | D10: 2 | E10: 75 | F10: 3675 | G10: 44100
B11: Feb 2027 | C11: 27 | D11: 2 | E11: 100 | F11: 4900 | G11: 58800
B12: Mar 2027 | C12: 30 | D12: 3 | E12: 127 | F12: 6223 | G12: 74676
B13: Apr 2027 | C13: 33 | D13: 4 | E13: 156 | F13: 7644 | G13: 91728
B14: May 2027 | C14: 36 | D14: 5 | E14: 187 | F14: 9163 | G14: 109956
B15: Jun 2027 | C15: 39 | D15: 6 | E15: 220 | F15: 10780 | G15: 129360
B16: Jul 2027 | C16: 42 | D16: 7 | E16: 255 | F16: 12495 | G16: 149940
B17: Aug 2027 | C17: 45 | D17: 8 | E17: 292 | F17: 14308 | G17: 171696
B18: Sep 2027 | C18: 48 | D18: 9 | E18: 331 | F18: 16219 | G18: 194628
... B21: Dec 2027 | C21: 57 | D21: 12 | E21: 460 | F21: 22540 | G21: 270480
B22: Dec 2027 — end of model | E22: 460 | F22: 22540 | G22: 270480
B24: BASE · 25 teams at launch / +5 teams / month
B25: Month | C25: New teams | D25: Churned | E25: Cumulative teams | F25: MRR | G25: ARR (run-rate)
B26: Oct 2026 | C26: 25 | D26: 0 | E26: 25 | F26: 1225 | G26: 14700
B27: Nov 2026 | C27: 30 | D27: 1 | E27: 54 | F27: 2646 | G27: 31752
B28: Dec 2026 | C28: 35 | D28: 2 | E28: 87 | F28: 4263 | G28: 51156
B29: Jan 2027 | C29: 40 | D29: 3 | E29: 124 | F29: 6076 | G29: 72912
B30: Feb 2027 | C30: 45 | D30: 4 | E30: 165 | F30: 8085 | G30: 97020
B31: Mar 2027 | C31: 50 | D31: 5 | E31: 210 | F31: 10290 | G31: 123480
B32: Apr 2027 | C32: 55 | D32: 6 | E32: 259 | F32: 12691 | G32: 152292
B33: May 2027 | C33: 60 | D33: 8 | E33: 311 | F33: 15239 | G33: 182868
B34: Jun 2027 | C34: 65 | D34: 9 | E34: 367 | F34: 17983 | G34: 215796
B35: Jul 2027 | C35: 70 | D35: 11 | E35: 426 | F35: 20874 | G35: 250488
B36: Aug 2027 | C36: 75 | D36: 13 | E36: 488 | F36: 23912 | G36: 286944
B37: Sep 2027 | C37: 80 | D37: 15 | E37: 553 | F37: 27097 | G37: 325164
... B40: Dec 2027 | C40: 95 | D40: 21 | E40: 766 | F40: 37534 | G40: 450408
B41: Dec 2027 — end of model | E41: 766 | F41: 37534 | G41: 450408
B43: OPTIMISTIC · 40 teams at launch / +8 teams / month
B44: Month | C44: New teams | D44: Churned | E44: Cumulative teams | F44: MRR | G44: ARR (run-rate)
B45: Oct 2026 | C45: 40 | D45: 0 | E45: 40 | F45: 1960 | G45: 23520
B46: Nov 2026 | C46: 48 | D46: 1 | E46: 87 | F46: 4263 | G46: 51156
B47: Dec 2026 | C47: 56 | D47: 3 | E47: 140 | F47: 6860 | G47: 82320
B48: Jan 2027 | C48: 64 | D48: 4 | E48: 200 | F48: 9800 | G48: 117600
...

Sheet Burn & Cash
B2: Burn & Cash Position · Base Scenario
B3: Seed of $1.5M closes May 2026. Revenue starts Oct 2026. Base scenario projections.
B5: Month | C5: Revenue (MRR) | D5: COGS | E5: Gross Profit | F5: Engineering | G5: GTM Spend | H5: Infra (OpEx) | I5: Net Burn / Mo | J5: Cash Remaining
B6: May 2026 | C6: 0 | D6: 0 | E6: 0 | F6: 29167 | G6: 45833 | H6: 8333 | I6: -83333 | J6: 1416667
B7: Jun 2026 | C7: 0 | D7: 0 | E7: 0 | F7: 29167 | G7: 45833 | H7: 8333 | I7: -83333 | J7: 1333334
B8: Jul 2026 | C8: 0 | D8: 0 | E8: 0 | F8: 29167 | G8: 45833 | H8: 8333 | I8: -83333 | J8: 1250001
B9: Aug 2026 | C9: 0 | D9: 0 | E9: 0 | F9: 29167 | G9: 45833 | H9: 8333 | I9: -83333 | J9: 1166668
B10: Sep 2026 | C10: 0 | D10: 0 | E10: 0 | F10: 29167 | G10: 45833 | H10: 8333 | I10: -83333 | J10: 1083335
B11: Oct 2026 | C11: 1225 | D11: 7 | E11: 1218 | F11: 29167 | G11: 45833 | H11: 8333 | I11: -82115 | J11: 1001220
B12: Nov 2026 | C12: 2646 | D12: 16 | E12: 2630 | F12: 29167 | G12: 45833 | H12: 8333 | I12: -80703 | J12: 920517
B13: Dec 2026 | C13: 4263 | D13: 26 | E13: 4237 | F13: 29167 | G13: 45833 | H13: 8333 | I13: -79096 | J13: 841421
B14: Jan 2027 | C14: 6076 | D14: 36 | E14: 6040 | F14: 29167 | G14: 45833 | H14: 8333 | I14: -77293 | J14: 764128
B15: Feb 2027 | C15: 8085 | D15: 49 | E15: 8036 | F15: 29167 | G15: 45833 | H15: 8333 | I15: -75297 | J15: 688831
B16: Mar 2027 | C16: 10290 | D16: 62 | E16: 10228 | F16: 29167 | G16: 45833 | H16: 8333 | I16: -73105 | J16: 615726
B17: Apr 2027 | C17: 12691 | D17: 76 | E17: 12615 | F17: 29167 | G17: 45833 | H17: 8333 | I17: -70718 | J17: 545008
... B25: Dec 2027 | C25: 37534 | D25: 225 | E25: 37309 | F25: 29167 | G25: 45833 | H25: 8333 | I25: -46024 | J25: 84079
B27: NOTES: • Revenue = $0 until Oct 2026 (paid tier launch). Pre-revenue months are pure burn. • COGS is ~0.6% of MRR. The local-first architecture keeps infrastructure costs negligible. • Engineering, GTM, and Infra are drawn as flat monthly allocations from the seed. • Cash turns amber when <$600k remaining (Series A prep territory), red when <$200k (runway risk). • Base scenario reaches ~$18k MRR / $216k ARR by June 2027. Monthly burn stays ~$83k. Revenue only partially offsets burn by Series A — the raise bridges to profitability post-Series A. • To model a different scenario: go to Inputs sheet, change scenario values, and re-run the model (or adjust the Projections sheet to see Conservative / Optimistic cash curves). Series A target: raise ~$5–8M on $150–350k ARR traction. Use of funds: scale GTM + add 2 engineers.
